<mujoco>

   <option integrator="RK4" timestep="0.001" >
   </option>
   <worldbody>
      <light diffuse=".5 .5 .5" pos="0 0 3" dir="0 0 -1"/>    
      <geom type="plane" size="1 1 0.1" rgba=".1 .1 .1 1" friction="1.0 0.005 0001"/>
      <body name="box" pos="0 0 0.1">
         <freejoint name="box"/>
         <geom name="box" type="box" size=".1 .1 .1" rgba=".8 0 .6 1" friction = "1.0 0.005 0001" mass="1.5"/> 
         <!-- "0.0 0.005 0.0001"/> -->
         <body name="com_offset" pos="0.0 0.1 0.12">
            <geom name="offset_mass" type="sphere" size="0.02" mass="1.0"/>
         </body>
      </body>
      <body name="pusher" pos="-0.2 0.0 0.1">
         <joint name="pusher_x" type="slide" axis="1 0 0" damping="0.0"/>
         <joint name="pusher_y" type="slide" axis="0 1 0" damping="0.0"/>
         <geom name="pusher" type="sphere" size="0.05" pos="0 0 0" euler="0.0 -90.0 0" friction="1.0 0.005 0001"/>
      </body>
   </worldbody>
   <actuator>
      <general name="push_velocity" joint="box"/>
      <general name="push_angle" joint="box"/>
      <!-- <motor name="sphere_x" joint="pusher_x" gear="100"/> -->
    </actuator>
</mujoco>
