<mujoco>
   <option integrator="RK4" timestep="0.001" >
   </option>
   <visual>
      <headlight ambient=".4 .4 .4" diffuse=".8 .8 .8" specular="0.1 0.1 0.1"/>
   </visual>
   <asset>
      <!-- <texture name="box_texture" type="cube" fileright="fileright.png" fileleft="fileleft.png" fileup="fileup.png" filedown="filedown.png" filefront="filefront.png" fileback="fileback.png"/> -->
      <texture name="box_texture" type="2d" builtin="flat" rgb1="1. 0.8 0.8"  width="800" height="800"/>
      <material name="box_material" texture="box_texture"/>

      <texture name="skybox" type="skybox" builtin="gradient" rgb1=".5 .7 .8" rgb2="0 0 0"
               width="800" height="800" mark="random" random="0.005" markrgb="1 .8 .8"/>
      <texture name="table" type="2d" builtin="flat" rgb1=".8 .8 .8"
               width="800" height="800"/>
      <material name="table" texture="table" specular="1.0" reflectance="0.2"/>   
   </asset>
   <worldbody>
      <light diffuse=".5 .5 .5" pos="0 0 3" dir="0 0 -1"/>    
      <geom name="plane" type="plane" material="table" size="0 0 0.05" rgba=".1 .1 .1 1" friction="0.01 0.005 0.0001"/>
      <body name="box" pos="0 0 0.1">
         <freejoint name="box"/>
         <geom name="box" type="box" size=".1 .1 .1" rgba=".8 0 .6 1" friction = "1.0 0.005 0001" mass="1.5" material="box_material"/> 
         <!-- "0.0 0.005 0.0001"/> -->
         <body name="com_offset" pos="0.0 0.0 0.12">
            <geom name="offset_mass" type="sphere" size="0.02" mass="0.5"/>
         </body>
      </body>
      <body name="pusher" pos="-0.2 0.0 0.1">
         <joint name="pusher_x" type="slide" axis="1 0 0" damping="0.0"/>
         <joint name="pusher_y" type="slide" axis="0 1 0" damping="0.0"/>
         <geom name="pusher" type="sphere" size="0.05" pos="0 0 0" euler="0.0 -90.0 0" friction="1.0 0.005 0001"/>
      </body>
   </worldbody>
   <actuator>
      <general name="start_x" joint="box"/>
      <general name="start_y" joint="box"/>
      <general name="push_angle" joint="box"/>
      <general name="push_vel" joint="box"/>
      <general name="push_time" joint="box"/>
      <general name="new_push" joint="box"/>
    </actuator>
</mujoco>
