<mujoco>

   <option integrator="RK4" timestep="0.001" >
   </option>
   <visual>
      <headlight ambient=".4 .4 .4" diffuse=".8 .8 .8" specular="0.1 0.1 0.1"/>
   </visual>
   <asset>
      <texture name="skybox" type="skybox" builtin="gradient" rgb1=".5 .7 .8" rgb2="0 0 0"
               width="800" height="800" mark="random" random="0.005" markrgb="1 .8 .8"/>
      <texture name="table" type="2d" builtin="flat" rgb1=".8 .8 .8"
               width="800" height="800"/>
      <material name="table" texture="table" specular="1.0" reflectance="0.2"/>   
  </asset>
   <worldbody>
      <light diffuse=".5 .5 .5" pos="0 0 3" dir="0 0 -1"/>    
      <!-- <geom name="plane" type="plane" material="table" size="0 0 0.05" rgba=".1 .1 .1 1" friction="0.01 0.005 0.0001"/> -->
      <body name="box" pos="0 0 0.1">
         <freejoint name="box"/>
         <geom name="box" type="box" size=".1 .1 .1" rgba=".8 0 .6 1" friction = "1.0 0.005 0001" mass="15"/> 
         <!-- "0.0 0.005 0.0001"/> -->
         <body name="com_offset" pos="0.0 0.1 0.12">
            <geom name="offset_mass" type="sphere" size="0.02" mass="10"/>
         </body>
      </body>
      <body name="pusher" pos="-0.5 0.0 0.1">
         <joint name="pusher_x" type="slide" axis="1 0 0" damping="1.0"/>
         <joint name="pusher_y" type="slide" axis="0 1 0" damping="40.0"/>
         <!-- <joint name="pusher_z" type="slide" axis="0 0 1" damping="20.0"/> -->
         <!-- <joint name="pusher_alpha" type="hinge" axis="1 0 0" damping="2.0"/> -->
         <!-- <joint name="pusher_beta" type="hinge" axis="0 1 0" damping="2.0"/> -->
         <!-- <joint name="pusher_zeta" type="hinge" axis="0 0 1" damping="2.0"/> -->
         <!-- <freejoint name="pusher"/> -->
         <geom name="pusher" type="capsule" size="0.05 0.1" pos="0.15 0 0" euler="0.0 -90.0 0" friction="1.0 0.005 0001"/>
         <!-- <site name="pusher"/> -->
      </body>
   </worldbody>
   <actuator>
      <velocity ctrllimited="true" ctrlrange="0 2" joint="pusher_x" kv="1000.0"/>
      <position ctrllimited="true" ctrlrange="-0.2 0.2" joint="pusher_y" kp="500.0"/>
      <!-- <motor joint="pusher_y"/> -->
      <!-- <position joint="pusher_z" kp="200.0"/> -->
      <!-- <position joint="pusher_alpha" kp="100.0"/> -->
      <!-- <position joint="pusher_bet a" kp="100.0"/> -->
      <!-- <position joint="pusher_zeta" kp="100.0"/> -->
    </actuator>
    <!-- <sensor>
      <velocimeter name="y_vel" site="pusher" noise="0.1"/>
    </sensor> -->
    <!-- <equality>
         <joint name="y_hold" joint1="pusher_y"/>
    </equality> -->
</mujoco>
